Traceback (most recent call last):
  File "/scratch/wbg231/dey_work/TxGNN/run.py", line 1, in <module>
    from txgnn import TxData, TxGNN, TxEval
  File "/scratch/wbg231/dey_work/TxGNN/txgnn/__init__.py", line 1, in <module>
    from .TxData import TxData
  File "/scratch/wbg231/dey_work/TxGNN/txgnn/TxData.py", line 9, in <module>
    import dgl
  File "/ext3/miniconda3/lib/python3.11/site-packages/dgl/__init__.py", line 14, in <module>
    from .backend import backend_name, load_backend  # usort: skip
    ^^^^^^^^^^^^^^^^^^^^^^^^^^^^^^^^^^^^^^^^^^^^^^^
  File "/ext3/miniconda3/lib/python3.11/site-packages/dgl/backend/__init__.py", line 122, in <module>
    load_backend(get_preferred_backend())
  File "/ext3/miniconda3/lib/python3.11/site-packages/dgl/backend/__init__.py", line 37, in load_backend
    import torch
  File "/ext3/miniconda3/lib/python3.11/site-packages/torch/__init__.py", line 234, in <module>
    _load_global_deps()
  File "/ext3/miniconda3/lib/python3.11/site-packages/torch/__init__.py", line 193, in _load_global_deps
    raise err
  File "/ext3/miniconda3/lib/python3.11/site-packages/torch/__init__.py", line 174, in _load_global_deps
    ctypes.CDLL(lib_path, mode=ctypes.RTLD_GLOBAL)
  File "/ext3/miniconda3/lib/python3.11/ctypes/__init__.py", line 376, in __init__
    self._handle = _dlopen(self._name, mode)
                   ^^^^^^^^^^^^^^^^^^^^^^^^^
OSError: /ext3/miniconda3/lib/python3.11/site-packages/torch/lib/libtorch_global_deps.so: cannot open shared object file: No such file or directory
